Workbook

Sheet Temperature Output
A1: Target Temp. | B1: Output Temp. | C1: Measured Res. | D1: Measured Temp. | E1: Delta Target-Output Temp. | F1: Delta Measured-Output Temp. | G1: Delta Target-Measured Temp.
A2: 30 | B2: 29.71 | C2: 5430 | D2: =1/('NTC PAW-A2W-TSOD'!$J$12+'NTC PAW-A2W-TSOD'!$J$13*LN(C2)+'NTC PAW-A2W-TSOD'!$J$14*(LN(C2))^3)-273.15 -> 29.524484 | E2: =A2-B2 -> 0.29 | F2: =D2-B2 -> -0.18551583 | G2: =A2-D2 -> 0.47551583
A3: 29.8 | B3: 29.71 | C3: 5430 | D3: =1/('NTC PAW-A2W-TSOD'!$J$12+'NTC PAW-A2W-TSOD'!$J$13*LN(C3)+'NTC PAW-A2W-TSOD'!$J$14*(LN(C3))^3)-273.15 -> 29.524484 | E3: =A3-B3 -> 0.09 | F3: =D3-B3 -> -0.18551583 | G3: =A3-D3 -> 0.27551583
A4: 29.6 | B4: 29.71 | C4: 5430 | D4: =1/('NTC PAW-A2W-TSOD'!$J$12+'NTC PAW-A2W-TSOD'!$J$13*LN(C4)+'NTC PAW-A2W-TSOD'!$J$14*(LN(C4))^3)-273.15 -> 29.524484 | E4: =A4-B4 -> -0.11 | F4: =D4-B4 -> -0.18551583 | G4: =A4-D4 -> 0.075515835
A5: 29.4 | B5: 29.71 | C5: 5430 | D5: =1/('NTC PAW-A2W-TSOD'!$J$12+'NTC PAW-A2W-TSOD'!$J$13*LN(C5)+'NTC PAW-A2W-TSOD'!$J$14*(LN(C5))^3)-273.15 -> 29.524484 | E5: =A5-B5 -> -0.31 | F5: =D5-B5 -> -0.18551583 | G5: =A5-D5 -> -0.12448417
A6: 29.2 | B6: 28.83 | C6: 5615 | D6: =1/('NTC PAW-A2W-TSOD'!$J$12+'NTC PAW-A2W-TSOD'!$J$13*LN(C6)+'NTC PAW-A2W-TSOD'!$J$14*(LN(C6))^3)-273.15 -> 28.689449 | E6: =A6-B6 -> 0.37 | F6: =D6-B6 -> -0.14055116 | G6: =A6-D6 -> 0.51055116
A7: 29 | B7: 28.83 | C7: 5615 | D7: =1/('NTC PAW-A2W-TSOD'!$J$12+'NTC PAW-A2W-TSOD'!$J$13*LN(C7)+'NTC PAW-A2W-TSOD'!$J$14*(LN(C7))^3)-273.15 -> 28.689449 | E7: =A7-B7 -> 0.17 | F7: =D7-B7 -> -0.14055116 | G7: =A7-D7 -> 0.31055116
A8: 28.8 | B8: 28.83 | C8: 5615 | D8: =1/('NTC PAW-A2W-TSOD'!$J$12+'NTC PAW-A2W-TSOD'!$J$13*LN(C8)+'NTC PAW-A2W-TSOD'!$J$14*(LN(C8))^3)-273.15 -> 28.689449 | E8: =A8-B8 -> -0.03 | F8: =D8-B8 -> -0.14055116 | G8: =A8-D8 -> 0.11055116
A9: 28.6 | B9: 28.83 | C9: 5615 | D9: =1/('NTC PAW-A2W-TSOD'!$J$12+'NTC PAW-A2W-TSOD'!$J$13*LN(C9)+'NTC PAW-A2W-TSOD'!$J$14*(LN(C9))^3)-273.15 -> 28.689449 | E9: =A9-B9 -> -0.23 | F9: =D9-B9 -> -0.14055116 | G9: =A9-D9 -> -0.089448844
A10: 28.4 | B10: 28.83 | C10: 5615 | D10: =1/('NTC PAW-A2W-TSOD'!$J$12+'NTC PAW-A2W-TSOD'!$J$13*LN(C10)+'NTC PAW-A2W-TSOD'!$J$14*(LN(C10))^3)-273.15 -> 28.689449 | E10: =A10-B10 -> -0.43 | F10: =D10-B10 -> -0.14055116 | G10: =A10-D10 -> -0.28944884
A11: 28.2 | B11: 27.98 | C11: 5808 | D11: =1/('NTC PAW-A2W-TSOD'!$J$12+'NTC PAW-A2W-TSOD'!$J$13*LN(C11)+'NTC PAW-A2W-TSOD'!$J$14*(LN(C11))^3)-273.15 -> 27.851015 | E11: =A11-B11 -> 0.22 | F11: =D11-B11 -> -0.12898464 | G11: =A11-D11 -> 0.34898464
A12: 28 | B12: 27.98 | C12: 5808 | D12: =1/('NTC PAW-A2W-TSOD'!$J$12+'NTC PAW-A2W-TSOD'!$J$13*LN(C12)+'NTC PAW-A2W-TSOD'!$J$14*(LN(C12))^3)-273.15 -> 27.851015 | E12: =A12-B12 -> 0.02 | F12: =D12-B12 -> -0.12898464 | G12: =A12-D12 -> 0.14898464
A13: 27.8 | B13: 27.98 | C13: 5808 | D13: =1/('NTC PAW-A2W-TSOD'!$J$12+'NTC PAW-A2W-TSOD'!$J$13*LN(C13)+'NTC PAW-A2W-TSOD'!$J$14*(LN(C13))^3)-273.15 -> 27.851015 | E13: =A13-B13 -> -0.18 | F13: =D13-B13 -> -0.12898464 | G13: =A13-D13 -> -0.051015359
... A252: -20 | B252: -20.03 | C252: 53230 | D252: =1/('NTC PAW-A2W-TSOD'!$J$12+'NTC PAW-A2W-TSOD'!$J$13*LN(C252)+'NTC PAW-A2W-TSOD'!$J$14*(LN(C252))^3)-273.15 -> -19.821869 | E252: =A252-B252 -> 0.03 | F252: =D252-B252 -> 0.20813134 | G252: =A252-D252 -> -0.17813134

Sheet Adjustment
A1: Temperature | B1: Real | C1: Adjusted | D1: Offset
A2: 30 | B2: 30 | C2: =$C$11-$B$11+B2 -> 34
A3: 29 | B3: 29 | C3: =$C$11-$B$11+B3 -> 33
A4: 28 | B4: 28 | C4: =$C$11-$B$11+B4 -> 32
A5: 27 | B5: 27 | C5: =$C$11-$B$11+B5 -> 31
A6: 26 | B6: 26 | C6: =$C$11-$B$11+B6 -> 30
A7: 25 | B7: 25 | C7: =$C$11-$B$11+B7 -> 29
A8: 24 | B8: 24 | C8: =$C$11-$B$11+B8 -> 28
A9: 23 | B9: 23 | C9: =$C$11-$B$11+B9 -> 27
A10: 22 | B10: 22 | C10: =$C$11-$B$11+B10 -> 26
A11: 21 | B11: 21 | C11: =B11+D11 -> 25 | D11: 4
A12: 20 | B12: 20 | C12: =B12+D12 -> 24 | D12: 4
A13: 19 | B13: 19 | C13: =B13+D13 -> 23 | D13: 4
A14: 18 | B14: 18 | C14: =B14+D14 -> 21 | D14: 3
A15: 17 | B15: 17 | C15: =B15+D15 -> 20 | D15: 3
A16: 16 | B16: 16 | C16: =B16+D16 -> 19 | D16: 3
A17: 15 | B17: 15 | C17: =B17+D17 -> 18 | D17: 3
A18: 14 | B18: 14 | C18: =B18+D18 -> 17 | D18: 3
A19: 13 | B19: 13 | C19: =B19+D19 -> 16 | D19: 3
A20: 12 | B20: 12 | C20: =B20+D20 -> 15 | D20: 3
A21: 11 | B21: 11 | C21: =B21+D21 -> 13 | D21: 2
A22: 10 | B22: 10 | C22: =B22+D22 -> 12 | D22: 2
... A47: -15 | B47: -15 | C47: =B47+D47 -> -18 | D47: -3
A48: -16 | B48: -16 | C48: =$C$47-$B$47+B48 -> -19
A49: -17 | B49: -17 | C49: =$C$47-$B$47+B49 -> -20
A50: -18 | B50: -18 | C50: =$C$47-$B$47+B50 -> -21
A51: -19 | B51: -19 | C51: =$C$47-$B$47+B51 -> -22
A52: -20 | B52: -20 | C52: =$C$47-$B$47+B52 -> -23

Sheet NTC PAW-A2W-TSOD
A1: Temp C | B1: k Ohm | C1: Ohm | D1: Calculated Resistance | F1: Calculated Temp | J1: Temp C | K1: Resistance | L1: Temp K | M1: LnR
A2: 150 | B2: 0.147 | C2: =B2*1000 -> 147 | D2: -40 | E2: =EXP(((SQRT(($J$13/(3*$J$14))^3+((($J$12-(1/(D2+273.15)))/$J$14)^2)/4))-((($J$12-(1/(D2+273.15)))/$J$14)/2))^(1/3)-((SQRT(($J$13/(3*$J$14))^3+((($J$12-(1/(D2+273.15)))/$J$14)^2)/4))+((($J$12-(1/(D2+273.15)))/$J$14)/2))^(1/3)) -> 167820 | F2: =E2 -> 167820 | G2: =1/($J$12+$J$13*LN(F2)+$J$14*(LN(F2))^3)-273.15 -> -40 | I2: Low | J2: -40 | K2: 167820 | L2: =J2+273.15 -> 233.15 | M2: =LN(K2) -> 12.030647
A3: 140 | B3: 0.186 | C3: =B3*1000 -> 186 | D3: =D2+1 -> -39 | E3: =EXP(((SQRT(($J$13/(3*$J$14))^3+((($J$12-(1/(D3+273.15)))/$J$14)^2)/4))-((($J$12-(1/(D3+273.15)))/$J$14)/2))^(1/3)-((SQRT(($J$13/(3*$J$14))^3+((($J$12-(1/(D3+273.15)))/$J$14)^2)/4))+((($J$12-(1/(D3+273.15)))/$J$14)/2))^(1/3)) -> 157974.86 | F3: =E3 -> 157974.86 | G3: =1/($J$12+$J$13*LN(F3)+$J$14*(LN(F3))^3)-273.15 -> -39 | I3: Mid | J3: 25 | K3: 6523 | L3: =J3+273.15 -> 298.15 | M3: =LN(K3) -> 8.7830897
A4: 130 | B4: 0.236 | C4: =B4*1000 -> 236 | D4: =D3+1 -> -38 | E4: =EXP(((SQRT(($J$13/(3*$J$14))^3+((($J$12-(1/(D4+273.15)))/$J$14)^2)/4))-((($J$12-(1/(D4+273.15)))/$J$14)/2))^(1/3)-((SQRT(($J$13/(3*$J$14))^3+((($J$12-(1/(D4+273.15)))/$J$14)^2)/4))+((($J$12-(1/(D4+273.15)))/$J$14)/2))^(1/3)) -> 148765.36 | F4: =E4 -> 148765.36 | G4: =1/($J$12+$J$13*LN(F4)+$J$14*(LN(F4))^3)-273.15 -> -38 | I4: High | J4: 120 | K4: 302 | L4: =J4+273.15 -> 393.15 | M4: =LN(K4) -> 5.710427
A5: 120 | B5: 0.302 | C5: =B5*1000 -> 302 | D5: =D4+1 -> -37 | E5: =EXP(((SQRT(($J$13/(3*$J$14))^3+((($J$12-(1/(D5+273.15)))/$J$14)^2)/4))-((($J$12-(1/(D5+273.15)))/$J$14)/2))^(1/3)-((SQRT(($J$13/(3*$J$14))^3+((($J$12-(1/(D5+273.15)))/$J$14)^2)/4))+((($J$12-(1/(D5+273.15)))/$J$14)/2))^(1/3)) -> 140146.97 | F5: =E5 -> 140146.97 | G5: =1/($J$12+$J$13*LN(F5)+$J$14*(LN(F5))^3)-273.15 -> -37
A6: 110 | B6: 0.39 | C6: =B6*1000 -> 390 | D6: =D5+1 -> -36 | E6: =EXP(((SQRT(($J$13/(3*$J$14))^3+((($J$12-(1/(D6+273.15)))/$J$14)^2)/4))-((($J$12-(1/(D6+273.15)))/$J$14)/2))^(1/3)-((SQRT(($J$13/(3*$J$14))^3+((($J$12-(1/(D6+273.15)))/$J$14)^2)/4))+((($J$12-(1/(D6+273.15)))/$J$14)/2))^(1/3)) -> 132078.52 | F6: =E6 -> 132078.52 | G6: =1/($J$12+$J$13*LN(F6)+$J$14*(LN(F6))^3)-273.15 -> -36 | I6: Ln(R1) - Ln(R2) | J6: =M2-M3 -> 3.2475576
A7: 100 | B7: 0.511 | C7: =B7*1000 -> 511 | D7: =D6+1 -> -35 | E7: =EXP(((SQRT(($J$13/(3*$J$14))^3+((($J$12-(1/(D7+273.15)))/$J$14)^2)/4))-((($J$12-(1/(D7+273.15)))/$J$14)/2))^(1/3)-((SQRT(($J$13/(3*$J$14))^3+((($J$12-(1/(D7+273.15)))/$J$14)^2)/4))+((($J$12-(1/(D7+273.15)))/$J$14)/2))^(1/3)) -> 124521.89 | F7: =E7 -> 124521.89 | G7: =1/($J$12+$J$13*LN(F7)+$J$14*(LN(F7))^3)-273.15 -> -35 | I7: Ln(R1) - Ln(R3) | J7: =M2-M4 -> 6.3202202
A8: 90 | B8: 0.686 | C8: =B8*1000 -> 686 | D8: =D7+1 -> -34 | E8: =EXP(((SQRT(($J$13/(3*$J$14))^3+((($J$12-(1/(D8+273.15)))/$J$14)^2)/4))-((($J$12-(1/(D8+273.15)))/$J$14)/2))^(1/3)-((SQRT(($J$13/(3*$J$14))^3+((($J$12-(1/(D8+273.15)))/$J$14)^2)/4))+((($J$12-(1/(D8+273.15)))/$J$14)/2))^(1/3)) -> 117441.82 | F8: =E8 -> 117441.82 | G8: =1/($J$12+$J$13*LN(F8)+$J$14*(LN(F8))^3)-273.15 -> -34 | I8: (1/T1) - (1/T2) | J8: =(1/L2) - (1/L3) -> 0.00093506785
A9: 80 | B9: 0.932 | C9: =B9*1000 -> 932 | D9: =D8+1 -> -33 | E9: =EXP(((SQRT(($J$13/(3*$J$14))^3+((($J$12-(1/(D9+273.15)))/$J$14)^2)/4))-((($J$12-(1/(D9+273.15)))/$J$14)/2))^(1/3)-((SQRT(($J$13/(3*$J$14))^3+((($J$12-(1/(D9+273.15)))/$J$14)^2)/4))+((($J$12-(1/(D9+273.15)))/$J$14)/2))^(1/3)) -> 110805.66 | F9: =E9 -> 110805.66 | G9: =1/($J$12+$J$13*LN(F9)+$J$14*(LN(F9))^3)-273.15 -> -33 | I9: (1/T1) - (1/T3) | J9: =(1/L2)-(1/L4) -> 0.0017455258
A10: 70 | B10: 1.279 | C10: =B10*1000 -> 1279 | D10: =D9+1 -> -32 | E10: =EXP(((SQRT(($J$13/(3*$J$14))^3+((($J$12-(1/(D10+273.15)))/$J$14)^2)/4))-((($J$12-(1/(D10+273.15)))/$J$14)/2))^(1/3)-((SQRT(($J$13/(3*$J$14))^3+((($J$12-(1/(D10+273.15)))/$J$14)^2)/4))+((($J$12-(1/(D10+273.15)))/$J$14)/2))^(1/3)) -> 104583.16 | F10: =E10 -> 104583.16 | G10: =1/($J$12+$J$13*LN(F10)+$J$14*(LN(F10))^3)-273.15 -> -32
A11: 65 | B11: 1.504 | C11: =B11*1000 -> 1504 | D11: =D10+1 -> -31 | E11: =EXP(((SQRT(($J$13/(3*$J$14))^3+((($J$12-(1/(D11+273.15)))/$J$14)^2)/4))-((($J$12-(1/(D11+273.15)))/$J$14)/2))^(1/3)-((SQRT(($J$13/(3*$J$14))^3+((($J$12-(1/(D11+273.15)))/$J$14)^2)/4))+((($J$12-(1/(D11+273.15)))/$J$14)/2))^(1/3)) -> 98746.304 | F11: =E11 -> 98746.304 | G11: =1/($J$12+$J$13*LN(F11)+$J$14*(LN(F11))^3)-273.15 -> -31 | I11: Coefficients
A12: 60 | B12: 1.777 | C12: =B12*1000 -> 1777 | D12: =D11+1 -> -30 | E12: =EXP(((SQRT(($J$13/(3*$J$14))^3+((($J$12-(1/(D12+273.15)))/$J$14)^2)/4))-((($J$12-(1/(D12+273.15)))/$J$14)/2))^(1/3)-((SQRT(($J$13/(3*$J$14))^3+((($J$12-(1/(D12+273.15)))/$J$14)^2)/4))+((($J$12-(1/(D12+273.15)))/$J$14)/2))^(1/3)) -> 93269.091 | F12: =E12 -> 93269.091 | G12: =1/($J$12+$J$13*LN(F12)+$J$14*(LN(F12))^3)-273.15 -> -30 | I12: a= | J12: =1/L2-J14*M2^3-J13*M2 -> 0.001142141
A13: 55 | B13: 2.106 | C13: =B13*1000 -> 2106 | D13: =D12+1 -> -29 | E13: =EXP(((SQRT(($J$13/(3*$J$14))^3+((($J$12-(1/(D13+273.15)))/$J$14)^2)/4))-((($J$12-(1/(D13+273.15)))/$J$14)/2))^(1/3)-((SQRT(($J$13/(3*$J$14))^3+((($J$12-(1/(D13+273.15)))/$J$14)^2)/4))+((($J$12-(1/(D13+273.15)))/$J$14)/2))^(1/3)) -> 88127.423 | F13: =E13 -> 88127.423 | G13: =1/($J$12+$J$13*LN(F13)+$J$14*(LN(F13))^3)-273.15 -> -29 | I13: b= | J13: =(J8-J14*(M2^3-M3^3))/J6 -> 0.00024071311
A14: 50 | B14: 2.508 | C14: =B14*1000 -> 2508 | D14: =D13+1 -> -28 | E14: =EXP(((SQRT(($J$13/(3*$J$14))^3+((($J$12-(1/(D14+273.15)))/$J$14)^2)/4))-((($J$12-(1/(D14+273.15)))/$J$14)/2))^(1/3)-((SQRT(($J$13/(3*$J$14))^3+((($J$12-(1/(D14+273.15)))/$J$14)^2)/4))+((($J$12-(1/(D14+273.15)))/$J$14)/2))^(1/3)) -> 83298.934 | F14: =E14 -> 83298.934 | G14: =1/($J$12+$J$13*LN(F14)+$J$14*(LN(F14))^3)-273.15 -> -28 | I14: c= | J14: =(J8-J6*J9/J7)/((M2^3-M3^3)-J6*(M2^3-M4^3)/J7) -> 1.441524e-07
A15: 45 | B15: 3.003 | C15: =B15*1000 -> 3003 | D15: =D14+1 -> -27 | E15: =EXP(((SQRT(($J$13/(3*$J$14))^3+((($J$12-(1/(D15+273.15)))/$J$14)^2)/4))-((($J$12-(1/(D15+273.15)))/$J$14)/2))^(1/3)-((SQRT(($J$13/(3*$J$14))^3+((($J$12-(1/(D15+273.15)))/$J$14)^2)/4))+((($J$12-(1/(D15+273.15)))/$J$14)/2))^(1/3)) -> 78762.866 | F15: =E15 -> 78762.866 | G15: =1/($J$12+$J$13*LN(F15)+$J$14*(LN(F15))^3)-273.15 -> -27
A16: 40 | B16: 3.615 | C16: =B16*1000 -> 3615 | D16: =D15+1 -> -26 | E16: =EXP(((SQRT(($J$13/(3*$J$14))^3+((($J$12-(1/(D16+273.15)))/$J$14)^2)/4))-((($J$12-(1/(D16+273.15)))/$J$14)/2))^(1/3)-((SQRT(($J$13/(3*$J$14))^3+((($J$12-(1/(D16+273.15)))/$J$14)^2)/4))+((($J$12-(1/(D16+273.15)))/$J$14)/2))^(1/3)) -> 74499.939 | F16: =E16 -> 74499.939 | G16: =1/($J$12+$J$13*LN(F16)+$J$14*(LN(F16))^3)-273.15 -> -26 | I16: Solving for R, given T: | K16: Resistance | L16: dR/dT | M16: %dR/dT | N16: alpha | O16: beta
A17: 35 | B17: 4.375 | C17: =B17*1000 -> 4375 | D17: =D16+1 -> -25 | E17: =EXP(((SQRT(($J$13/(3*$J$14))^3+((($J$12-(1/(D17+273.15)))/$J$14)^2)/4))-((($J$12-(1/(D17+273.15)))/$J$14)/2))^(1/3)-((SQRT(($J$13/(3*$J$14))^3+((($J$12-(1/(D17+273.15)))/$J$14)^2)/4))+((($J$12-(1/(D17+273.15)))/$J$14)/2))^(1/3)) -> 70492.244 | F17: =E17 -> 70492.244 | G17: =1/($J$12+$J$13*LN(F17)+$J$14*(LN(F17))^3)-273.15 -> -25 | I17: Degrees C= | J17: 15.49 | K17: =EXP((O17-(N17/2))^(1/3)-(O17+(N17/2))^(1/3)) -> 9740.3147 | L17: =-1*K17/(J18^2*($J$13+3*$J$14*(LN(K17))^2)) -> -421.77756 | M17: =L17/K17*100 -> -4.3302252 | N17: =($J$12-(1/J18))/$J$14 -> -16110.605 | O17: =SQRT(($J$13/(3*$J$14))^3+(N17^2)/4) -> 15405.861
A18: 30 | B18: 5.326 | C18: =B18*1000 -> 5326 | D18: =D17+1 -> -24 | E18: =EXP(((SQRT(($J$13/(3*$J$14))^3+((($J$12-(1/(D18+273.15)))/$J$14)^2)/4))-((($J$12-(1/(D18+273.15)))/$J$14)/2))^(1/3)-((SQRT(($J$13/(3*$J$14))^3+((($J$12-(1/(D18+273.15)))/$J$14)^2)/4))+((($J$12-(1/(D18+273.15)))/$J$14)/2))^(1/3)) -> 66723.136 | F18: =E18 -> 66723.136 | G18: =1/($J$12+$J$13*LN(F18)+$J$14*(LN(F18))^3)-273.15 -> -24 | I18: Temp K | J18: =J17+273.15 -> 288.64
A19: 25 | B19: 6.523 | C19: =B19*1000 -> 6523 | D19: =D18+1 -> -23 | E19: =EXP(((SQRT(($J$13/(3*$J$14))^3+((($J$12-(1/(D19+273.15)))/$J$14)^2)/4))-((($J$12-(1/(D19+273.15)))/$J$14)/2))^(1/3)-((SQRT(($J$13/(3*$J$14))^3+((($J$12-(1/(D19+273.15)))/$J$14)^2)/4))+((($J$12-(1/(D19+273.15)))/$J$14)/2))^(1/3)) -> 63177.141 | F19: =E19 -> 63177.141 | G19: =1/($J$12+$J$13*LN(F19)+$J$14*(LN(F19))^3)-273.15 -> -23
A20: 20 | B20: 8.044 | C20: =B20*1000 -> 8044 | D20: =D19+1 -> -22 | E20: =EXP(((SQRT(($J$13/(3*$J$14))^3+((($J$12-(1/(D20+273.15)))/$J$14)^2)/4))-((($J$12-(1/(D20+273.15)))/$J$14)/2))^(1/3)-((SQRT(($J$13/(3*$J$14))^3+((($J$12-(1/(D20+273.15)))/$J$14)^2)/4))+((($J$12-(1/(D20+273.15)))/$J$14)/2))^(1/3)) -> 59839.863 | F20: =E20 -> 59839.863 | G20: =1/($J$12+$J$13*LN(F20)+$J$14*(LN(F20))^3)-273.15 -> -22 | I20: Solving For T, given R: | K20: Temp C=
A21: 15 | B21: 9.98 | C21: =B21*1000 -> 9980 | D21: =D20+1 -> -21 | E21: =EXP(((SQRT(($J$13/(3*$J$14))^3+((($J$12-(1/(D21+273.15)))/$J$14)^2)/4))-((($J$12-(1/(D21+273.15)))/$J$14)/2))^(1/3)-((SQRT(($J$13/(3*$J$14))^3+((($J$12-(1/(D21+273.15)))/$J$14)^2)/4))+((($J$12-(1/(D21+273.15)))/$J$14)/2))^(1/3)) -> 56697.91 | F21: =E21 -> 56697.91 | G21: =1/($J$12+$J$13*LN(F21)+$J$14*(LN(F21))^3)-273.15 -> -21 | I21: Ohms= | J21: 9740 | K21: =1/(J12+J13*LN(J21)+J14*(LN(J21))^3)-273.15 -> 15.490746 | L21: =1/(J12+J13*LN(J21)+J14*(LN(J21))^3)-273.15 -> 15.490746 | M21: =LN((10240000/569)-10000) -> 8.9867574 | N21: =LN(((10240000/569)-10000)/10000) -> -0.22358302
A22: 10 | B22: 12.443 | C22: =B22*1000 -> 12443 | D22: =D21+1 -> -20 | E22: =EXP(((SQRT(($J$13/(3*$J$14))^3+((($J$12-(1/(D22+273.15)))/$J$14)^2)/4))-((($J$12-(1/(D22+273.15)))/$J$14)/2))^(1/3)-((SQRT(($J$13/(3*$J$14))^3+((($J$12-(1/(D22+273.15)))/$J$14)^2)/4))+((($J$12-(1/(D22+273.15)))/$J$14)/2))^(1/3)) -> 53738.817 | F22: =E22 -> 53738.817 | G22: =1/($J$12+$J$13*LN(F22)+$J$14*(LN(F22))^3)-273.15 -> -20 | M22: =1 / (0.001138942 + (0.000232762 + (0.000000091 * M21 * M21)) * M21) -> 303.32773 | N22: =1/(0.003354016+(0.000256985*N21)+(0.000002620131*N21*N21)) -> 303.3346
A23: 5 | B23: 15.604 | C23: =B23*1000 -> 15604 | D23: =D22+1 -> -19 | E23: =EXP(((SQRT(($J$13/(3*$J$14))^3+((($J$12-(1/(D23+273.15)))/$J$14)^2)/4))-((($J$12-(1/(D23+273.15)))/$J$14)/2))^(1/3)-((SQRT(($J$13/(3*$J$14))^3+((($J$12-(1/(D23+273.15)))/$J$14)^2)/4))+((($J$12-(1/(D23+273.15)))/$J$14)/2))^(1/3)) -> 50950.974 | F23: =E23 -> 50950.974 | G23: =1/($J$12+$J$13*LN(F23)+$J$14*(LN(F23))^3)-273.15 -> -19 | M23: =M22-273.15 -> 30.177729 | N23: =N22-273.15 -> 30.184603
A24: 0 | B24: 19.7 | C24: =B24*1000 -> 19700 | D24: =D23+1 -> -18 | E24: =EXP(((SQRT(($J$13/(3*$J$14))^3+((($J$12-(1/(D24+273.15)))/$J$14)^2)/4))-((($J$12-(1/(D24+273.15)))/$J$14)/2))^(1/3)-((SQRT(($J$13/(3*$J$14))^3+((($J$12-(1/(D24+273.15)))/$J$14)^2)/4))+((($J$12-(1/(D24+273.15)))/$J$14)/2))^(1/3)) -> 48323.568 | F24: =E24 -> 48323.568 | G24: =1/($J$12+$J$13*LN(F24)+$J$14*(LN(F24))^3)-273.15 -> -18
A25: -5 | B25: 25.05 | C25: =B25*1000 -> 25050 | D25: =D24+1 -> -17 | E25: =EXP(((SQRT(($J$13/(3*$J$14))^3+((($J$12-(1/(D25+273.15)))/$J$14)^2)/4))-((($J$12-(1/(D25+273.15)))/$J$14)/2))^(1/3)-((SQRT(($J$13/(3*$J$14))^3+((($J$12-(1/(D25+273.15)))/$J$14)^2)/4))+((($J$12-(1/(D25+273.15)))/$J$14)/2))^(1/3)) -> 45846.522 | F25: =E25 -> 45846.522 | G25: =1/($J$12+$J$13*LN(F25)+$J$14*(LN(F25))^3)-273.15 -> -17
A26: -10 | B26: 32.1 | C26: =B26*1000 -> 32100 | D26: =D25+1 -> -16 | E26: =EXP(((SQRT(($J$13/(3*$J$14))^3+((($J$12-(1/(D26+273.15)))/$J$14)^2)/4))-((($J$12-(1/(D26+273.15)))/$J$14)/2))^(1/3)-((SQRT(($J$13/(3*$J$14))^3+((($J$12-(1/(D26+273.15)))/$J$14)^2)/4))+((($J$12-(1/(D26+273.15)))/$J$14)/2))^(1/3)) -> 43510.442 | F26: =E26 -> 43510.442 | G26: =1/($J$12+$J$13*LN(F26)+$J$14*(LN(F26))^3)-273.15 -> -16
A27: -15 | B27: 41.45 | C27: =B27*1000 -> 41450 | D27: =D26+1 -> -15 | E27: =EXP(((SQRT(($J$13/(3*$J$14))^3+((($J$12-(1/(D27+273.15)))/$J$14)^2)/4))-((($J$12-(1/(D27+273.15)))/$J$14)/2))^(1/3)-((SQRT(($J$13/(3*$J$14))^3+((($J$12-(1/(D27+273.15)))/$J$14)^2)/4))+((($J$12-(1/(D27+273.15)))/$J$14)/2))^(1/3)) -> 41306.567 | F27: =E27 -> 41306.567 | G27: =1/($J$12+$J$13*LN(F27)+$J$14*(LN(F27))^3)-273.15 -> -15
A28: -20 | B28: 53.92 | C28: =B28*1000 -> 53920 | D28: =D27+1 -> -14 | E28: =EXP(((SQRT(($J$13/(3*$J$14))^3+((($J$12-(1/(D28+273.15)))/$J$14)^2)/4))-((($J$12-(1/(D28+273.15)))/$J$14)/2))^(1/3)-((SQRT(($J$13/(3*$J$14))^3+((($J$12-(1/(D28+273.15)))/$J$14)^2)/4))+((($J$12-(1/(D28+273.15)))/$J$14)/2))^(1/3)) -> 39226.725 | F28: =E28 -> 39226.725 | G28: =1/($J$12+$J$13*LN(F28)+$J$14*(LN(F28))^3)-273.15 -> -14
A29: -25 | B29: 70.53 | C29: =B29*1000 -> 70530 | D29: =D28+1 -> -13 | E29: =EXP(((SQRT(($J$13/(3*$J$14))^3+((($J$12-(1/(D29+273.15)))/$J$14)^2)/4))-((($J$12-(1/(D29+273.15)))/$J$14)/2))^(1/3)-((SQRT(($J$13/(3*$J$14))^3+((($J$12-(1/(D29+273.15)))/$J$14)^2)/4))+((($J$12-(1/(D29+273.15)))/$J$14)/2))^(1/3)) -> 37263.288 | F29: =E29 -> 37263.288 | G29: =1/($J$12+$J$13*LN(F29)+$J$14*(LN(F29))^3)-273.15 -> -13
A30: -30 | B30: 93.05 | C30: =B30*1000 -> 93050 | D30: =D29+1 -> -12 | E30: =EXP(((SQRT(($J$13/(3*$J$14))^3+((($J$12-(1/(D30+273.15)))/$J$14)^2)/4))-((($J$12-(1/(D30+273.15)))/$J$14)/2))^(1/3)-((SQRT(($J$13/(3*$J$14))^3+((($J$12-(1/(D30+273.15)))/$J$14)^2)/4))+((($J$12-(1/(D30+273.15)))/$J$14)/2))^(1/3)) -> 35409.135 | F30: =E30 -> 35409.135 | G30: =1/($J$12+$J$13*LN(F30)+$J$14*(LN(F30))^3)-273.15 -> -12
A31: -35 | B31: 124.24 | C31: =B31*1000 -> 124240 | D31: =D30+1 -> -11 | E31: =EXP(((SQRT(($J$13/(3*$J$14))^3+((($J$12-(1/(D31+273.15)))/$J$14)^2)/4))-((($J$12-(1/(D31+273.15)))/$J$14)/2))^(1/3)-((SQRT(($J$13/(3*$J$14))^3+((($J$12-(1/(D31+273.15)))/$J$14)^2)/4))+((($J$12-(1/(D31+273.15)))/$J$14)/2))^(1/3)) -> 33657.616 | F31: =E31 -> 33657.616 | G31: =1/($J$12+$J$13*LN(F31)+$J$14*(LN(F31))^3)-273.15 -> -11
A32: -40 | B32: 167.82 | C32: =B32*1000 -> 167820 | D32: =D31+1 -> -10 | E32: =EXP(((SQRT(($J$13/(3*$J$14))^3+((($J$12-(1/(D32+273.15)))/$J$14)^2)/4))-((($J$12-(1/(D32+273.15)))/$J$14)/2))^(1/3)-((SQRT(($J$13/(3*$J$14))^3+((($J$12-(1/(D32+273.15)))/$J$14)^2)/4))+((($J$12-(1/(D32+273.15)))/$J$14)/2))^(1/3)) -> 32002.518 | F32: =E32 -> 32002.518 | G32: =1/($J$12+$J$13*LN(F32)+$J$14*(LN(F32))^3)-273.15 -> -10
D33: =D32+1 -> -9 | E33: =EXP(((SQRT(($J$13/(3*$J$14))^3+((($J$12-(1/(D33+273.15)))/$J$14)^2)/4))-((($J$12-(1/(D33+273.15)))/$J$14)/2))^(1/3)-((SQRT(($J$13/(3*$J$14))^3+((($J$12-(1/(D33+273.15)))/$J$14)^2)/4))+((($J$12-(1/(D33+273.15)))/$J$14)/2))^(1/3)) -> 30438.034 | F33: =E33 -> 30438.034 | G33: =1/($J$12+$J$13*LN(F33)+$J$14*(LN(F33))^3)-273.15 -> -9
D34: =D33+1 -> -8 | E34: =EXP(((SQRT(($J$13/(3*$J$14))^3+((($J$12-(1/(D34+273.15)))/$J$14)^2)/4))-((($J$12-(1/(D34+273.15)))/$J$14)/2))^(1/3)-((SQRT(($J$13/(3*$J$14))^3+((($J$12-(1/(D34+273.15)))/$J$14)^2)/4))+((($J$12-(1/(D34+273.15)))/$J$14)/2))^(1/3)) -> 28958.737 | F34: =E34 -> 28958.737 | G34: =1/($J$12+$J$13*LN(F34)+$J$14*(LN(F34))^3)-273.15 -> -8
D35: =D34+1 -> -7 | E35: =EXP(((SQRT(($J$13/(3*$J$14))^3+((($J$12-(1/(D35+273.15)))/$J$14)^2)/4))-((($J$12-(1/(D35+273.15)))/$J$14)/2))^(1/3)-((SQRT(($J$13/(3*$J$14))^3+((($J$12-(1/(D35+273.15)))/$J$14)^2)/4))+((($J$12-(1/(D35+273.15)))/$J$14)/2))^(1/3)) -> 27559.548 | F35: =E35 -> 27559.548 | G35: =1/($J$12+$J$13*LN(F35)+$J$14*(LN(F35))^3)-273.15 -> -7
D36: =D35+1 -> -6 | E36: =EXP(((SQRT(($J$13/(3*$J$14))^3+((($J$12-(1/(D36+273.15)))/$J$14)^2)/4))-((($J$12-(1/(D36+273.15)))/$J$14)/2))^(1/3)-((SQRT(($J$13/(3*$J$14))^3+((($J$12-(1/(D36+273.15)))/$J$14)^2)/4))+((($J$12-(1/(D36+273.15)))/$J$14)/2))^(1/3)) -> 26235.718 | F36: =E36 -> 26235.718 | G36: =1/($J$12+$J$13*LN(F36)+$J$14*(LN(F36))^3)-273.15 -> -6
D37: =D36+1 -> -5 | E37: =EXP(((SQRT(($J$13/(3*$J$14))^3+((($J$12-(1/(D37+273.15)))/$J$14)^2)/4))-((($J$12-(1/(D37+273.15)))/$J$14)/2))^(1/3)-((SQRT(($J$13/(3*$J$14))^3+((($J$12-(1/(D37+273.15)))/$J$14)^2)/4))+((($J$12-(1/(D37+273.15)))/$J$14)/2))^(1/3)) -> 24982.802 | F37: =E37 -> 24982.802 | G37: =1/($J$12+$J$13*LN(F37)+$J$14*(LN(F37))^3)-273.15 -> -5
D38: =D37+1 -> -4 | E38: =EXP(((SQRT(($J$13/(3*$J$14))^3+((($J$12-(1/(D38+273.15)))/$J$14)^2)/4))-((($J$12-(1/(D38+273.15)))/$J$14)/2))^(1/3)-((SQRT(($J$13/(3*$J$14))^3+((($J$12-(1/(D38+273.15)))/$J$14)^2)/4))+((($J$12-(1/(D38+273.15)))/$J$14)/2))^(1/3)) -> 23796.639 | F38: =E38 -> 23796.639 | G38: =1/($J$12+$J$13*LN(F38)+$J$14*(LN(F38))^3)-273.15 -> -4
D39: =D38+1 -> -3 | E39: =EXP(((SQRT(($J$13/(3*$J$14))^3+((($J$12-(1/(D39+273.15)))/$J$14)^2)/4))-((($J$12-(1/(D39+273.15)))/$J$14)/2))^(1/3)-((SQRT(($J$13/(3*$J$14))^3+((($J$12-(1/(D39+273.15)))/$J$14)^2)/4))+((($J$12-(1/(D39+273.15)))/$J$14)/2))^(1/3)) -> 22673.331 | F39: =E39 -> 22673.331 | G39: =1/($J$12+$J$13*LN(F39)+$J$14*(LN(F39))^3)-273.15 -> -3
D40: =D39+1 -> -2 | E40: =EXP(((SQRT(($J$13/(3*$J$14))^3+((($J$12-(1/(D40+273.15)))/$J$14)^2)/4))-((($J$12-(1/(D40+273.15)))/$J$14)/2))^(1/3)-((SQRT(($J$13/(3*$J$14))^3+((($J$12-(1/(D40+273.15)))/$J$14)^2)/4))+((($J$12-(1/(D40+273.15)))/$J$14)/2))^(1/3)) -> 21609.227 | F40: =E40 -> 21609.227 | G40: =1/($J$12+$J$13*LN(F40)+$J$14*(LN(F40))^3)-273.15 -> -2
...

Sheet MCP4151
A1: Step | B1: Resistance | C1: Temperature | E1: Pre-Resist | F1: Pre-Resistor | G1: Steps | H1: Step Res.: | J1: R | K1: Pos | M1: Pos: | N1: R
A2: =A3+1 -> 256 | B2: =B3+$H$2 -> 50000 | C2: =1/('NTC PAW-A2W-TSOD'!$J$12+'NTC PAW-A2W-TSOD'!$J$13*LN(B2)+'NTC PAW-A2W-TSOD'!$J$14*(LN(B2))^3)-273.15 -> -18.644844 | E2: 3300 | F2: 50000 | G2: 257 | H2: =$F$2/$G$2 -> 194.55253 | J2: 42607 | K2: =(J2/(F2/G2))-1 -> 217.99998 | M2: 218 | N2: =($F$2/$G$2) + ((M2)*($F$2/$G$2)) -> 42607.004
A3: =A4+1 -> 255 | B3: =B4+$H$2 -> 49805.447 | C3: =1/('NTC PAW-A2W-TSOD'!$J$12+'NTC PAW-A2W-TSOD'!$J$13*LN(B3)+'NTC PAW-A2W-TSOD'!$J$14*(LN(B3))^3)-273.15 -> -18.571257
A4: =A5+1 -> 254 | B4: =B5+$H$2 -> 49610.895 | C4: =1/('NTC PAW-A2W-TSOD'!$J$12+'NTC PAW-A2W-TSOD'!$J$13*LN(B4)+'NTC PAW-A2W-TSOD'!$J$14*(LN(B4))^3)-273.15 -> -18.497347
A5: =A6+1 -> 253 | B5: =B6+$H$2 -> 49416.342 | C5: =1/('NTC PAW-A2W-TSOD'!$J$12+'NTC PAW-A2W-TSOD'!$J$13*LN(B5)+'NTC PAW-A2W-TSOD'!$J$14*(LN(B5))^3)-273.15 -> -18.423114
A6: =A7+1 -> 252 | B6: =B7+$H$2 -> 49221.79 | C6: =1/('NTC PAW-A2W-TSOD'!$J$12+'NTC PAW-A2W-TSOD'!$J$13*LN(B6)+'NTC PAW-A2W-TSOD'!$J$14*(LN(B6))^3)-273.15 -> -18.348554
A7: =A8+1 -> 251 | B7: =B8+$H$2 -> 49027.237 | C7: =1/('NTC PAW-A2W-TSOD'!$J$12+'NTC PAW-A2W-TSOD'!$J$13*LN(B7)+'NTC PAW-A2W-TSOD'!$J$14*(LN(B7))^3)-273.15 -> -18.273664
A8: =A9+1 -> 250 | B8: =B9+$H$2 -> 48832.685 | C8: =1/('NTC PAW-A2W-TSOD'!$J$12+'NTC PAW-A2W-TSOD'!$J$13*LN(B8)+'NTC PAW-A2W-TSOD'!$J$14*(LN(B8))^3)-273.15 -> -18.198441
A9: =A10+1 -> 249 | B9: =B10+$H$2 -> 48638.132 | C9: =1/('NTC PAW-A2W-TSOD'!$J$12+'NTC PAW-A2W-TSOD'!$J$13*LN(B9)+'NTC PAW-A2W-TSOD'!$J$14*(LN(B9))^3)-273.15 -> -18.122883
A10: =A11+1 -> 248 | B10: =B11+$H$2 -> 48443.58 | C10: =1/('NTC PAW-A2W-TSOD'!$J$12+'NTC PAW-A2W-TSOD'!$J$13*LN(B10)+'NTC PAW-A2W-TSOD'!$J$14*(LN(B10))^3)-273.15 -> -18.046987
A11: =A12+1 -> 247 | B11: =B12+$H$2 -> 48249.027 | C11: =1/('NTC PAW-A2W-TSOD'!$J$12+'NTC PAW-A2W-TSOD'!$J$13*LN(B11)+'NTC PAW-A2W-TSOD'!$J$14*(LN(B11))^3)-273.15 -> -17.97075
A12: =A13+1 -> 246 | B12: =B13+$H$2 -> 48054.475 | C12: =1/('NTC PAW-A2W-TSOD'!$J$12+'NTC PAW-A2W-TSOD'!$J$13*LN(B12)+'NTC PAW-A2W-TSOD'!$J$14*(LN(B12))^3)-273.15 -> -17.894169
A13: =A14+1 -> 245 | B13: =B14+$H$2 -> 47859.922 | C13: =1/('NTC PAW-A2W-TSOD'!$J$12+'NTC PAW-A2W-TSOD'!$J$13*LN(B13)+'NTC PAW-A2W-TSOD'!$J$14*(LN(B13))^3)-273.15 -> -17.817241
A14: =A15+1 -> 244 | B14: =B15+$H$2 -> 47665.37 | C14: =1/('NTC PAW-A2W-TSOD'!$J$12+'NTC PAW-A2W-TSOD'!$J$13*LN(B14)+'NTC PAW-A2W-TSOD'!$J$14*(LN(B14))^3)-273.15 -> -17.739963
... A257: =A258+1 -> 1 | B257: =B258+$H$2 -> 389.10506 | C257: =1/('NTC PAW-A2W-TSOD'!$J$12+'NTC PAW-A2W-TSOD'!$J$13*LN(B257)+'NTC PAW-A2W-TSOD'!$J$14*(LN(B257))^3)-273.15 -> 110.24218
A258: 0 | B258: =$H$2 -> 194.55253 | C258: =1/('NTC PAW-A2W-TSOD'!$J$12+'NTC PAW-A2W-TSOD'!$J$13*LN(B258)+'NTC PAW-A2W-TSOD'!$J$14*(LN(B258))^3)-273.15 -> 138.03841

Sheet Parallel Resistor
A1: R | B1: Ts | C1: Tm | D1: Td | F1: Parallel Resistor
A2: ='NTC PAW-A2W-TSOD'!F2*$F$2/('NTC PAW-A2W-TSOD'!F2+$F$2) -> 51834.692 | B2: ='NTC PAW-A2W-TSOD'!G2 -> -40 | C2: =1/('NTC PAW-A2W-TSOD'!$J$12+'NTC PAW-A2W-TSOD'!$J$13*LN(A2)+'NTC PAW-A2W-TSOD'!$J$14*(LN(A2))^3)-273.15 -> -19.323469 | D2: =C2-B2 -> 20.676531 | F2: 75000
A3: ='NTC PAW-A2W-TSOD'!F3*$F$2/('NTC PAW-A2W-TSOD'!F3+$F$2) -> 50855.764 | B3: ='NTC PAW-A2W-TSOD'!G3 -> -39 | C3: =1/('NTC PAW-A2W-TSOD'!$J$12+'NTC PAW-A2W-TSOD'!$J$13*LN(A3)+'NTC PAW-A2W-TSOD'!$J$14*(LN(A3))^3)-273.15 -> -18.964777 | D3: =C3-B3 -> 20.035223
A4: ='NTC PAW-A2W-TSOD'!F4*$F$2/('NTC PAW-A2W-TSOD'!F4+$F$2) -> 49862.061 | B4: ='NTC PAW-A2W-TSOD'!G4 -> -38 | C4: =1/('NTC PAW-A2W-TSOD'!$J$12+'NTC PAW-A2W-TSOD'!$J$13*LN(A4)+'NTC PAW-A2W-TSOD'!$J$14*(LN(A4))^3)-273.15 -> -18.592703 | D4: =C4-B4 -> 19.407297
A5: ='NTC PAW-A2W-TSOD'!F5*$F$2/('NTC PAW-A2W-TSOD'!F5+$F$2) -> 48855.082 | B5: ='NTC PAW-A2W-TSOD'!G5 -> -37 | C5: =1/('NTC PAW-A2W-TSOD'!$J$12+'NTC PAW-A2W-TSOD'!$J$13*LN(A5)+'NTC PAW-A2W-TSOD'!$J$14*(LN(A5))^3)-273.15 -> -18.207118 | D5: =C5-B5 -> 18.792882
A6: ='NTC PAW-A2W-TSOD'!F6*$F$2/('NTC PAW-A2W-TSOD'!F6+$F$2) -> 47836.39 | B6: ='NTC PAW-A2W-TSOD'!G6 -> -36 | C6: =1/('NTC PAW-A2W-TSOD'!$J$12+'NTC PAW-A2W-TSOD'!$J$13*LN(A6)+'NTC PAW-A2W-TSOD'!$J$14*(LN(A6))^3)-273.15 -> -17.807913 | D6: =C6-B6 -> 18.192087
A7: ='NTC PAW-A2W-TSOD'!F7*$F$2/('NTC PAW-A2W-TSOD'!F7+$F$2) -> 46807.604 | B7: ='NTC PAW-A2W-TSOD'!G7 -> -35 | C7: =1/('NTC PAW-A2W-TSOD'!$J$12+'NTC PAW-A2W-TSOD'!$J$13*LN(A7)+'NTC PAW-A2W-TSOD'!$J$14*(LN(A7))^3)-273.15 -> -17.395 | D7: =C7-B7 -> 17.605
A8: ='NTC PAW-A2W-TSOD'!F8*$F$2/('NTC PAW-A2W-TSOD'!F8+$F$2) -> 45770.386 | B8: ='NTC PAW-A2W-TSOD'!G8 -> -34 | C8: =1/('NTC PAW-A2W-TSOD'!$J$12+'NTC PAW-A2W-TSOD'!$J$13*LN(A8)+'NTC PAW-A2W-TSOD'!$J$14*(LN(A8))^3)-273.15 -> -16.968314 | D8: =C8-B8 -> 17.031686
A9: ='NTC PAW-A2W-TSOD'!F9*$F$2/('NTC PAW-A2W-TSOD'!F9+$F$2) -> 44726.433 | B9: ='NTC PAW-A2W-TSOD'!G9 -> -33 | C9: =1/('NTC PAW-A2W-TSOD'!$J$12+'NTC PAW-A2W-TSOD'!$J$13*LN(A9)+'NTC PAW-A2W-TSOD'!$J$14*(LN(A9))^3)-273.15 -> -16.52781 | D9: =C9-B9 -> 16.47219
A10: ='NTC PAW-A2W-TSOD'!F10*$F$2/('NTC PAW-A2W-TSOD'!F10+$F$2) -> 43677.465 | B10: ='NTC PAW-A2W-TSOD'!G10 -> -32 | C10: =1/('NTC PAW-A2W-TSOD'!$J$12+'NTC PAW-A2W-TSOD'!$J$13*LN(A10)+'NTC PAW-A2W-TSOD'!$J$14*(LN(A10))^3)-273.15 -> -16.073467 | D10: =C10-B10 -> 15.926533
A11: ='NTC PAW-A2W-TSOD'!F11*$F$2/('NTC PAW-A2W-TSOD'!F11+$F$2) -> 42625.211 | B11: ='NTC PAW-A2W-TSOD'!G11 -> -31 | C11: =1/('NTC PAW-A2W-TSOD'!$J$12+'NTC PAW-A2W-TSOD'!$J$13*LN(A11)+'NTC PAW-A2W-TSOD'!$J$14*(LN(A11))^3)-273.15 -> -15.605284 | D11: =C11-B11 -> 15.394716
A12: ='NTC PAW-A2W-TSOD'!F12*$F$2/('NTC PAW-A2W-TSOD'!F12+$F$2) -> 41571.401 | B12: ='NTC PAW-A2W-TSOD'!G12 -> -30 | C12: =1/('NTC PAW-A2W-TSOD'!$J$12+'NTC PAW-A2W-TSOD'!$J$13*LN(A12)+'NTC PAW-A2W-TSOD'!$J$14*(LN(A12))^3)-273.15 -> -15.123281 | D12: =C12-B12 -> 14.876719
A13: ='NTC PAW-A2W-TSOD'!F13*$F$2/('NTC PAW-A2W-TSOD'!F13+$F$2) -> 40517.754 | B13: ='NTC PAW-A2W-TSOD'!G13 -> -29 | C13: =1/('NTC PAW-A2W-TSOD'!$J$12+'NTC PAW-A2W-TSOD'!$J$13*LN(A13)+'NTC PAW-A2W-TSOD'!$J$14*(LN(A13))^3)-273.15 -> -14.627502 | D13: =C13-B13 -> 14.372498
A14: ='NTC PAW-A2W-TSOD'!F14*$F$2/('NTC PAW-A2W-TSOD'!F14+$F$2) -> 39465.964 | B14: ='NTC PAW-A2W-TSOD'!G14 -> -28 | C14: =1/('NTC PAW-A2W-TSOD'!$J$12+'NTC PAW-A2W-TSOD'!$J$13*LN(A14)+'NTC PAW-A2W-TSOD'!$J$14*(LN(A14))^3)-273.15 -> -14.118009 | D14: =C14-B14 -> 13.881991
... A192: ='NTC PAW-A2W-TSOD'!F192*$F$2/('NTC PAW-A2W-TSOD'!F192+$F$2) -> 147.82798 | B192: ='NTC PAW-A2W-TSOD'!G192 -> 150 | C192: =1/('NTC PAW-A2W-TSOD'!$J$12+'NTC PAW-A2W-TSOD'!$J$13*LN(A192)+'NTC PAW-A2W-TSOD'!$J$14*(LN(A192))^3)-273.15 -> 150.08887 | D192: =C192-B192 -> 0.088871371
